<sdf version='1.7'>
  <model name='xxx'>
    <link name='base_footprint'>
      <inertial>
        <pose>0.0002 0.0001 0.1649 0 -0 0</pose>
        <mass>40</mass>
        <inertia>
          <ixx>1.79367</ixx>
          <ixy>0</ixy>
          <ixz>0</ixz>
          <iyy>1.28667</iyy>
          <iyz>0</iyz>
          <izz>2.30967</izz>
        </inertia>
      </inertial>
      <collision name='base_footprint_fixed_joint_lump__base_link_collision'>
        <pose>0 0 0.165 0 -0 0</pose>
        <geometry>
          <box>
            <size>0.65 0.55 0.25</size>
          </box>
        </geometry>
      </collision>
      <collision name='base_footprint_fixed_joint_lump__back_left_pole_collision_1'>
        <pose>-0.125 0.125 0.315 0 -0 0</pose>
        <geometry>
          <cylinder>
            <length>0.05</length>
            <radius>0.015</radius>
          </cylinder>
        </geometry>
      </collision>
      <collision name='base_footprint_fixed_joint_lump__back_right_pole_collision_2'>
        <pose>-0.125 -0.125 0.315 0 -0 0</pose>
        <geometry>
          <cylinder>
            <length>0.05</length>
            <radius>0.015</radius>
          </cylinder>
        </geometry>
      </collision>
      <collision name='base_footprint_fixed_joint_lump__front_left_pole_collision_3'>
        <pose>0.125 0.125 0.315 0 -0 0</pose>
        <geometry>
          <cylinder>
            <length>0.05</length>
            <radius>0.015</radius>
          </cylinder>
        </geometry>
      </collision>
      <collision name='base_footprint_fixed_joint_lump__front_right_pole_collision_4'>
        <pose>0.125 -0.125 0.315 0 -0 0</pose>
        <geometry>
          <cylinder>
            <length>0.05</length>
            <radius>0.015</radius>
          </cylinder>
        </geometry>
      </collision>
      <visual name='base_footprint_fixed_joint_lump__base_link_visual'>
        <pose>0 0 0.147 0 -0 1.5708</pose>
        <geometry>
          <mesh>
            <uri>file://coconut.stl</uri>
            <scale>1 1 1</scale>
          </mesh>
        </geometry>
      </visual>
      <visual name='base_footprint_fixed_joint_lump__back_left_pole_visual_1'>
        <pose>-0.125 0.125 0.315 0 -0 0</pose>
        <geometry>
          <cylinder>
            <length>0.05</length>
            <radius>0.015</radius>
          </cylinder>
        </geometry>
      </visual>
      <visual name='base_footprint_fixed_joint_lump__back_right_pole_visual_2'>
        <pose>-0.125 -0.125 0.315 0 -0 0</pose>
        <geometry>
          <cylinder>
            <length>0.05</length>
            <radius>0.015</radius>
          </cylinder>
        </geometry>
      </visual>
      <visual name='base_footprint_fixed_joint_lump__camera_visual_3'>
        <pose>0.317 0 0.265 0 -0 0</pose>
        <geometry>
          <box>
            <size>0.025 0.09 0.025</size>
          </box>
        </geometry>
      </visual>
      <visual name='base_footprint_fixed_joint_lump__front_left_pole_visual_4'>
        <pose>0.125 0.125 0.315 0 -0 0</pose>
        <geometry>
          <cylinder>
            <length>0.05</length>
            <radius>0.015</radius>
          </cylinder>
        </geometry>
      </visual>
      <visual name='base_footprint_fixed_joint_lump__front_right_pole_visual_5'>
        <pose>0.125 -0.125 0.315 0 -0 0</pose>
        <geometry>
          <cylinder>
            <length>0.05</length>
            <radius>0.015</radius>
          </cylinder>
        </geometry>
      </visual>
      <visual name='base_footprint_fixed_joint_lump__lidar_visual_6'>
        <pose>0.22 0 0.31 0 -0 0</pose>
        <geometry>
          <cylinder>
            <length>0.04</length>
            <radius>0.035</radius>
          </cylinder>
        </geometry>
      </visual>
      <visual name='base_footprint_fixed_joint_lump__t265_visual_7'>
        <pose>-0.3195 -0.0081 0.335 0 -0 3.14159</pose>
        <geometry>
          <box>
            <size>0.025 0.09 0.025</size>
          </box>
        </geometry>
      </visual>
      <visual name='base_footprint_fixed_joint_lump__ultrasonic1_visual_8'>
        <pose>0.32 0.22 0.165 0 -0 0.087</pose>
        <geometry>
          <sphere>
            <radius>0.01</radius>
          </sphere>
        </geometry>
      </visual>
      <visual name='base_footprint_fixed_joint_lump__ultrasonic2_visual_9'>
        <pose>0.32 0.15 0.165 0 -0 0</pose>
        <geometry>
          <sphere>
            <radius>0.01</radius>
          </sphere>
        </geometry>
      </visual>
      <visual name='base_footprint_fixed_joint_lump__ultrasonic3_visual_10'>
        <pose>0.32 -0.15 0.165 0 -0 0</pose>
        <geometry>
          <sphere>
            <radius>0.01</radius>
          </sphere>
        </geometry>
      </visual>
      <visual name='base_footprint_fixed_joint_lump__ultrasonic4_visual_11'>
        <pose>0.32 -0.22 0.165 0 0 -0.087</pose>
        <geometry>
          <sphere>
            <radius>0.01</radius>
          </sphere>
        </geometry>
      </visual>
      <visual name='base_footprint_fixed_joint_lump__ultrasonic5_visual_12'>
        <pose>-0.29 -0.23 0.165 0 0 -2.71319</pose>
        <geometry>
          <sphere>
            <radius>0.01</radius>
          </sphere>
        </geometry>
      </visual>
      <visual name='base_footprint_fixed_joint_lump__ultrasonic6_visual_13'>
        <pose>-0.31 -0.17 0.165 0 0 -3.05319</pose>
        <geometry>
          <sphere>
            <radius>0.01</radius>
          </sphere>
        </geometry>
      </visual>
      <visual name='base_footprint_fixed_joint_lump__ultrasonic7_visual_14'>
        <pose>-0.31 0.17 0.165 0 -0 3.05</pose>
        <geometry>
          <sphere>
            <radius>0.01</radius>
          </sphere>
        </geometry>
      </visual>
      <visual name='base_footprint_fixed_joint_lump__ultrasonic8_visual_15'>
        <pose>-0.29 0.23 0.165 0 -0 2.7</pose>
        <geometry>
          <sphere>
            <radius>0.01</radius>
          </sphere>
        </geometry>
      </visual>
    </link>
    <joint name='left_front_castor_joint' type='revolute'>
      <pose relative_to='base_footprint'>0.23 -0.16 0.035 0 -0 0</pose>
      <parent>base_footprint</parent>
      <child>left_front_castor</child>
      <axis>
        <xyz>0 1 0</xyz>
        <limit>
          <lower>-1e+16</lower>
          <upper>1e+16</upper>
        </limit>
        <dynamics>
          <spring_reference>0</spring_reference>
          <spring_stiffness>0</spring_stiffness>
        </dynamics>
      </axis>
    </joint>
    <link name='left_front_castor'>
      <pose relative_to='left_front_castor_joint'>0 0 0 0 -0 0</pose>
      <inertial>
        <pose>0 0 0 0 -0 0</pose>
        <mass>0.2</mass>
        <inertia>
          <ixx>4.437e-05</ixx>
          <ixy>0</ixy>
          <ixz>0</ixz>
          <iyy>4.437e-05</iyy>
          <iyz>0</iyz>
          <izz>0.00047625</izz>
        </inertia>
      </inertial>
      <collision name='left_front_castor_collision'>
        <pose>0 0 0 1.5708 -0 0</pose>
        <geometry>
          <cylinder>
            <length>0.02</length>
            <radius>0.035</radius>
          </cylinder>
        </geometry>
      </collision>
      <visual name='left_front_castor_visual'>
        <pose>0 0 0 1.5708 -0 0</pose>
        <geometry>
          <cylinder>
            <length>0.02</length>
            <radius>0.035</radius>
          </cylinder>
        </geometry>
      </visual>
    </link>
    <joint name='left_rear_castor_joint' type='revolute'>
      <pose relative_to='base_footprint'>-0.23 -0.16 0.035 0 -0 0</pose>
      <parent>base_footprint</parent>
      <child>left_rear_castor</child>
      <axis>
        <xyz>0 1 0</xyz>
        <limit>
          <lower>-1e+16</lower>
          <upper>1e+16</upper>
        </limit>
        <dynamics>
          <spring_reference>0</spring_reference>
          <spring_stiffness>0</spring_stiffness>
        </dynamics>
      </axis>
    </joint>
    <link name='left_rear_castor'>
      <pose relative_to='left_rear_castor_joint'>0 0 0 0 -0 0</pose>
      <inertial>
        <pose>0 0 0 0 -0 0</pose>
        <mass>0.2</mass>
        <inertia>
          <ixx>4.437e-05</ixx>
          <ixy>0</ixy>
          <ixz>0</ixz>
          <iyy>4.437e-05</iyy>
          <iyz>0</iyz>
          <izz>0.00047625</izz>
        </inertia>
      </inertial>
      <collision name='left_rear_castor_collision'>
        <pose>0 0 0 1.5708 -0 0</pose>
        <geometry>
          <cylinder>
            <length>0.02</length>
            <radius>0.035</radius>
          </cylinder>
        </geometry>
      </collision>
      <visual name='left_rear_castor_visual'>
        <pose>0 0 0 1.5708 -0 0</pose>
        <geometry>
          <cylinder>
            <length>0.02</length>
            <radius>0.035</radius>
          </cylinder>
        </geometry>
      </visual>
    </link>
    <joint name='left_wheel_joint' type='revolute'>
      <pose relative_to='base_footprint'>0 0.225 0.08 0 -0 0</pose>
      <parent>base_footprint</parent>
      <child>left_wheel</child>
      <axis>
        <xyz>0 1 0</xyz>
        <limit>
          <effort>300</effort>
          <velocity>300</velocity>
          <lower>-1e+16</lower>
          <upper>1e+16</upper>
        </limit>
        <dynamics>
          <damping>0</damping>
          <friction>0</friction>
          <spring_reference>0</spring_reference>
          <spring_stiffness>0</spring_stiffness>
        </dynamics>
      </axis>
    </joint>
    <link name='left_wheel'>
      <pose relative_to='left_wheel_joint'>0 0 0 0 -0 0</pose>
      <inertial>
        <pose>0 0 0 0 -0 0</pose>
        <mass>2.9</mass>
        <inertia>
          <ixx>0.00564437</ixx>
          <ixy>0</ixy>
          <ixz>0</ixz>
          <iyy>0.00564437</iyy>
          <iyz>0</iyz>
          <izz>0.0104762</izz>
        </inertia>
      </inertial>
      <collision name='left_wheel_collision'>
        <pose>0 0 0 1.5708 -0 0</pose>
        <geometry>
          <cylinder>
            <length>0.04</length>
            <radius>0.08</radius>
          </cylinder>
        </geometry>
      </collision>
      <visual name='left_wheel_visual'>
        <pose>0 0 0 1.5708 -0 0</pose>
        <geometry>
          <cylinder>
            <length>0.04</length>
            <radius>0.08</radius>
          </cylinder>
        </geometry>
      </visual>
    </link>
    <joint name='right_front_castor_joint' type='revolute'>
      <pose relative_to='base_footprint'>0.23 0.16 0.035 0 -0 0</pose>
      <parent>base_footprint</parent>
      <child>right_front_castor</child>
      <axis>
        <xyz>0 1 0</xyz>
        <limit>
          <lower>-1e+16</lower>
          <upper>1e+16</upper>
        </limit>
        <dynamics>
          <spring_reference>0</spring_reference>
          <spring_stiffness>0</spring_stiffness>
        </dynamics>
      </axis>
    </joint>
    <link name='right_front_castor'>
      <pose relative_to='right_front_castor_joint'>0 0 0 0 -0 0</pose>
      <inertial>
        <pose>0 0 0 0 -0 0</pose>
        <mass>0.2</mass>
        <inertia>
          <ixx>4.437e-05</ixx>
          <ixy>0</ixy>
          <ixz>0</ixz>
          <iyy>4.437e-05</iyy>
          <iyz>0</iyz>
          <izz>0.00047625</izz>
        </inertia>
      </inertial>
      <collision name='right_front_castor_collision'>
        <pose>0 0 0 1.5708 -0 0</pose>
        <geometry>
          <cylinder>
            <length>0.02</length>
            <radius>0.035</radius>
          </cylinder>
        </geometry>
      </collision>
      <visual name='right_front_castor_visual'>
        <pose>0 0 0 1.5708 -0 0</pose>
        <geometry>
          <cylinder>
            <length>0.02</length>
            <radius>0.035</radius>
          </cylinder>
        </geometry>
      </visual>
    </link>
    <joint name='right_rear_castor_joint' type='revolute'>
      <pose relative_to='base_footprint'>-0.23 0.16 0.035 0 -0 0</pose>
      <parent>base_footprint</parent>
      <child>right_rear_castor</child>
      <axis>
        <xyz>0 1 0</xyz>
        <limit>
          <lower>-1e+16</lower>
          <upper>1e+16</upper>
        </limit>
        <dynamics>
          <spring_reference>0</spring_reference>
          <spring_stiffness>0</spring_stiffness>
        </dynamics>
      </axis>
    </joint>
    <link name='right_rear_castor'>
      <pose relative_to='right_rear_castor_joint'>0 0 0 0 -0 0</pose>
      <inertial>
        <pose>0 0 0 0 -0 0</pose>
        <mass>0.2</mass>
        <inertia>
          <ixx>4.437e-05</ixx>
          <ixy>0</ixy>
          <ixz>0</ixz>
          <iyy>4.437e-05</iyy>
          <iyz>0</iyz>
          <izz>0.00047625</izz>
        </inertia>
      </inertial>
      <collision name='right_rear_castor_collision'>
        <pose>0 0 0 1.5708 -0 0</pose>
        <geometry>
          <cylinder>
            <length>0.02</length>
            <radius>0.035</radius>
          </cylinder>
        </geometry>
      </collision>
      <visual name='right_rear_castor_visual'>
        <pose>0 0 0 1.5708 -0 0</pose>
        <geometry>
          <cylinder>
            <length>0.02</length>
            <radius>0.035</radius>
          </cylinder>
        </geometry>
      </visual>
    </link>
    <joint name='right_wheel_joint' type='revolute'>
      <pose relative_to='base_footprint'>0 -0.225 0.08 0 -0 0</pose>
      <parent>base_footprint</parent>
      <child>right_wheel</child>
      <axis>
        <xyz>0 1 0</xyz>
        <limit>
          <effort>300</effort>
          <velocity>300</velocity>
          <lower>-1e+16</lower>
          <upper>1e+16</upper>
        </limit>
        <dynamics>
          <damping>0</damping>
          <friction>0</friction>
          <spring_reference>0</spring_reference>
          <spring_stiffness>0</spring_stiffness>
        </dynamics>
      </axis>
    </joint>
    <link name='right_wheel'>
      <pose relative_to='right_wheel_joint'>0 0 0 0 -0 0</pose>
      <inertial>
        <pose>0 0 0 0 -0 0</pose>
        <mass>2.9</mass>
        <inertia>
          <ixx>0.00564437</ixx>
          <ixy>0</ixy>
          <ixz>0</ixz>
          <iyy>0.00564437</iyy>
          <iyz>0</iyz>
          <izz>0.0104762</izz>
        </inertia>
      </inertial>
      <collision name='right_wheel_collision'>
        <pose>0 0 0 1.5708 -0 0</pose>
        <geometry>
          <cylinder>
            <length>0.04</length>
            <radius>0.08</radius>
          </cylinder>
        </geometry>
      </collision>
      <visual name='right_wheel_visual'>
        <pose>0 0 0 1.5708 -0 0</pose>
        <geometry>
          <cylinder>
            <length>0.04</length>
            <radius>0.08</radius>
          </cylinder>
        </geometry>
      </visual>
    </link>
  </model>
</sdf>
