<?xml version="1.0"?>
<robot name="xxx_wheel" xmlns:xacro="http:///www.ros.org/wiki/xacro">
    <xacro:include filename="$(find xxx_description)/urdf/xxx_properties.xacro"/>
        <xacro:macro name="wheel" params="name translation rotation parent">

            <link name="${name}_wheel">
                <inertial>
                    <origin rpy="0.0 0.0 0.0" xyz="${WHEEL_COM}"/>
                    <mass value="${WHEEL_M}"/>
                   <inertia ixx="${WHEEL_Ixx}" ixy="${WHEEL_Ixy}" ixz="${WHEEL_Ixz}" iyy="${WHEEL_Iyy}" iyz="${WHEEL_Iyz}" izz="${WHEEL_Izz}"/>
                </inertial>
                <visual>
                    <origin rpy="${PI/2} 0.0 0.0" xyz="0.0 0.0 0.0"/>
                    <geometry>
                        <cylinder radius="${WHEEL_RADIUS}" length="0.04"/>
                    </geometry>
                    <material name="${name}_wheel_color">
                        <color rgba="${WHEEL_COLOR}"/>
                    </material>
                </visual>
                <collision>
                    <origin rpy="${PI/2} 0.0 0.0" xyz="0.0 0.0 0.0"/>
                    <geometry>
                        <cylinder radius="${WHEEL_RADIUS}" length="0.04"/>
                    </geometry>
                </collision>
            </link>
            <joint name="${name}_wheel_joint" type="continuous">
                <origin rpy="${rotation}" xyz="${translation}"/>
                <parent link="${parent}"/>
                <child link="${name}_wheel"/>
                <axis xyz="0.0 1.0 0.0"/>
                <limit effort="${U_MAX}" velocity="${V_MAX}"/>   
                <dynamics damping="${WHEEL_JOINT_DAMP}"/>
            </joint>
            
            <transmission name="${name}_wheel_motor">
                <type>transmission_interface/SimpleTransmission</type>
                <joint name="${name}_wheel_joint">
                    <hardwareInterface>hardware_interface/EffortJointInterface</hardwareInterface>
                </joint>
                <actuator name="${name}_wheel_motor">
                    <hardwareInterface>hardware_interface/EffortJointInterface</hardwareInterface>
                    <mechanicalReduction>1</mechanicalReduction>
                </actuator>
            </transmission>
        </xacro:macro>
</robot>
